biomesToSpawnIn=ocean,deep ocean,kelp forest,ocean oil field,oceanic abyss,coral reef
weight=1
embed_into_distance=-3
unacceptable_target_blocks=flowing_lava,lava,Natura:Cloud,grass
dimensions=10,53,7
allowable_overhang=12
max_leveling=5
leveling_buffer=-1
preserve_water=1
preserve_lava=0
preserve_plants=0
uniqueMinDistance=10000
spawnMinDistance=5000
spawnMaxDistance=0

rule1=0,100,preserveBlock
rule2=0,100,minecraft:stained_hardened_clay-9
rule3=0,100,minecraft:obsidian-0
rule4=0,100,minecraft:gold_block-0
rule5=0,100,quark:iron_plate-1
rule6=0,100,minecraft:piston-4
rule7=0,100,minecraft:piston-1
rule8=0,100,minecraft:redstone_block-0
rule9=0,100,minecraft:stained_glass_pane-15
rule10=0,100,air
rule11=0,100,minecraft:iron_door-2
rule12=0,100,minecraft:carpet-15
rule13=0,100,minecraft:bed-3
rule14=0,100,minecraft:bed-11
rule15=0,100,ChestGenHook:chests/village_blacksmith:9-3,ChestGenHook:chests/spawn_bonus_chest:9-3,ChestGenHook:chests/abandoned_mineshaft:9-3
rule16=0,100,ChestGenHook:chests/village_blacksmith:9-2,ChestGenHook:chests/nether_bridge:9-2,ChestGenHook:chests/stronghold_library:9-2
rule17=0,100,ChestGenHook:chests/village_blacksmith:9-3,ChestGenHook:chests/nether_bridge:9-3,ChestGenHook:chests/woodland_mansion:9-3
rule18=0,100,ChestGenHook:chests/stronghold_crossing:9-2,ChestGenHook:chests/woodland_mansion:9-2,ChestGenHook:chests/village_blacksmith:9-2
rule19=0,100,minecraft:crafting_table-0
rule20=0,100,ChestGenHook:chests/igloo_chest:9-3,ChestGenHook:chests/nether_bridge:9-3,ChestGenHook:chests/jungle_temple:9-3
rule21=0,100,ChestGenHook:chests/igloo_chest:9-2,ChestGenHook:chests/abandoned_mineshaft:9-2,ChestGenHook:chests/village_blacksmith:9-2
rule22=0,100,ChestGenHook:chests/igloo_chest:9-3,ChestGenHook:chests/nether_bridge:9-3,ChestGenHook:chests/jungle_temple:9-3
rule23=0,100,ChestGenHook:chests/igloo_chest:9-2,ChestGenHook:chests/abandoned_mineshaft:9-2,ChestGenHook:chests/village_blacksmith:9-2
rule24=0,100,minecraft:oak_stairs-0
rule25=0,100,minecraft:oak_stairs-1
rule26=0,100,minecraft:piston-3
rule27=0,100,minecraft:piston-2
rule28=0,100,minecraft:air
rule29=0,100,minecraft:iron_door-9
rule30=0,100,ChestGenHook:chests/woodland_mansion:9-3,ChestGenHook:chests/village_blacksmith:9-3,ChestGenHook:chests/spawn_bonus_chest:9-3
rule31=0,100,ChestGenHook:chests/simple_dungeon:9-2,ChestGenHook:chests/nether_bridge:9-2,ChestGenHook:chests/stronghold_library:9-2
rule32=0,100,ChestGenHook:chests/nether_bridge:9-3,ChestGenHook:chests/stronghold_crossing:9-3,ChestGenHook:chests/village_blacksmith:9-3
rule33=0,100,ChestGenHook:chests/simple_dungeon:9-2,ChestGenHook:chests/nether_bridge:9-2,ChestGenHook:chests/stronghold_corridor:9-2
rule34=0,100,ChestGenHook:chests/spawn_bonus_chest:9-3,ChestGenHook:chests/jungle_temple:9-3,ChestGenHook:chests/stronghold_library:9-3
rule35=0,100,ChestGenHook:chests/stronghold_crossing:9-2,ChestGenHook:chests/simple_dungeon:9-2,ChestGenHook:chests/woodland_mansion:9-2
rule36=0,100,ChestGenHook:chests/igloo_chest:9-3,ChestGenHook:chests/village_blacksmith:9-3,ChestGenHook:chests/stronghold_library:9-3
rule37=0,100,ChestGenHook:chests/nether_bridge:9-2,ChestGenHook:chests/stronghold_corridor:9-2,ChestGenHook:chests/abandoned_mineshaft:9-2
rule38=0,100,minecraft:stone_slab-0
rule39=0,100,minecraft:double_stone_slab-0
rule40=0,100,minecraft:piston-0
rule41=0,100,minecraft:iron_bars-0
rule42=0,100,ChestGenHook:chests/village_blacksmith:9-3,ChestGenHook:chests/spawn_bonus_chest:9-3,ChestGenHook:chests/abandoned_mineshaft:9-3
rule43=0,100,ChestGenHook:chests/village_blacksmith:9-2,ChestGenHook:chests/nether_bridge:9-2,ChestGenHook:chests/stronghold_library:9-2
rule44=0,100,ChestGenHook:chests/village_blacksmith:9-3,ChestGenHook:chests/nether_bridge:9-3,ChestGenHook:chests/woodland_mansion:9-3
rule45=0,100,ChestGenHook:chests/stronghold_crossing:9-2,ChestGenHook:chests/woodland_mansion:9-2,ChestGenHook:chests/village_blacksmith:9-2
rule46=0,100,ChestGenHook:chests/igloo_chest:9-3,ChestGenHook:chests/nether_bridge:9-3,ChestGenHook:chests/jungle_temple:9-3
rule47=0,100,ChestGenHook:chests/igloo_chest:9-2,ChestGenHook:chests/abandoned_mineshaft:9-2,ChestGenHook:chests/village_blacksmith:9-2
rule48=0,100,ChestGenHook:chests/nether_bridge:9-3,ChestGenHook:chests/stronghold_crossing:9-3,ChestGenHook:chests/village_blacksmith:9-3
rule49=0,100,ChestGenHook:chests/simple_dungeon:9-2,ChestGenHook:chests/nether_bridge:9-2,ChestGenHook:chests/stronghold_corridor:9-2
rule50=0,100,minecraft:iron_trapdoor-1
rule51=0,100,minecraft:stone-6
rule52=0,100,minecraft:iron_trapdoor-9

layer
1,1,1,1,1,1,1
1,1,1,1,1,1,1
1,1,1,2,1,1,1
1,1,1,1,1,1,1
1,1,1,1,1,1,1
1,1,1,1,1,1,1
1,1,1,1,1,1,1
1,1,1,1,1,1,1
1,1,1,1,1,1,1
1,1,1,2,1,1,1
1,1,1,2,1,1,1
1,1,1,2,1,1,1
1,1,1,2,1,1,1
1,1,2,2,2,1,1
1,1,2,2,2,1,1
1,1,2,2,2,1,1
1,1,2,2,2,1,1
1,1,2,2,2,1,1
1,1,2,2,2,1,1
1,1,2,2,2,1,1
1,1,2,2,2,1,1
1,1,2,2,2,1,1
1,1,2,2,2,1,1
1,1,2,2,2,1,1
1,1,2,2,2,1,1
1,1,2,2,2,1,1
1,1,2,2,2,1,1
1,1,2,2,2,1,1
1,1,2,2,2,1,1
1,1,2,2,2,1,1
1,1,2,2,2,1,1
1,1,2,2,2,1,1
1,1,2,2,2,1,1
1,1,2,2,2,1,1
1,1,2,2,2,1,1
1,1,2,2,2,1,1
1,1,2,2,2,1,1
1,1,2,2,2,1,1
1,1,2,2,2,1,1
1,1,2,2,2,1,1
1,1,2,2,2,1,1
1,1,2,2,2,1,1
1,1,2,2,2,1,1
1,1,2,2,2,1,1
1,1,2,2,2,1,1
1,1,2,2,2,1,1
1,1,2,2,2,1,1
1,1,1,2,1,1,1
1,1,1,2,1,1,1
1,1,1,2,1,1,1
1,1,1,1,1,1,1
1,1,1,1,1,1,1
1,1,1,1,1,1,1
endlayer

layer
1,1,1,1,1,1,1
1,1,1,1,1,1,1
1,1,1,2,1,1,1
1,1,1,2,1,1,1
1,1,1,1,1,1,1
1,1,1,2,1,1,1
1,1,1,2,1,1,1
1,1,2,2,2,1,1
1,1,2,2,2,1,1
1,1,2,2,2,1,1
1,1,2,2,2,1,1
1,2,2,2,2,2,1
1,2,2,2,2,2,1
1,2,3,3,3,2,1
1,2,3,3,3,2,1
1,2,3,3,3,2,1
1,2,3,3,3,2,1
1,2,3,3,3,2,1
1,2,3,3,3,2,1
1,2,3,3,3,2,1
1,2,3,3,3,2,1
1,2,3,3,3,2,1
1,2,3,3,3,2,1
1,2,3,3,3,2,1
1,2,3,3,3,2,1
1,2,3,3,3,2,1
1,2,3,3,3,2,1
1,2,3,3,3,2,1
1,2,3,3,3,2,1
1,2,3,3,3,2,1
1,2,3,3,3,2,1
1,2,3,3,3,2,1
1,2,3,3,3,2,1
1,2,3,3,3,2,1
1,2,3,3,3,2,1
1,2,3,3,3,2,1
1,2,3,3,3,2,1
1,2,3,3,3,2,1
1,2,3,3,3,2,1
1,2,3,3,3,2,1
1,2,3,3,3,2,1
1,2,3,3,3,2,1
1,2,3,3,3,2,1
1,2,3,3,3,2,1
1,2,3,3,3,2,1
1,2,3,3,3,2,1
1,2,3,3,3,2,1
1,2,2,2,2,2,1
1,1,2,2,2,1,1
1,1,2,2,2,1,1
1,1,2,2,2,1,1
1,1,1,2,1,1,1
1,1,1,1,1,1,1
endlayer

layer
1,1,1,4,1,1,1
1,1,1,1,1,1,1
1,1,1,2,1,1,1
1,1,1,2,1,1,1
1,1,1,2,1,1,1
1,1,2,2,2,1,1
1,1,2,2,2,1,1
1,2,5,5,5,2,1
1,2,6,7,6,2,1
1,2,5,5,5,2,1
1,2,8,8,8,2,1
1,2,8,8,8,2,1
1,2,3,3,3,2,1
2,3,8,8,8,3,2
2,3,9,9,9,3,2
2,3,10,10,10,3,2
2,3,10,10,10,3,2
2,3,10,10,10,3,2
2,3,2,11,2,3,2
2,3,2,12,2,3,2
2,3,13,12,13,3,2
2,3,14,12,14,3,2
2,3,2,12,2,3,2
2,3,13,12,13,3,2
2,3,14,12,14,3,2
2,3,2,12,2,3,2
2,3,13,12,13,3,2
2,3,14,12,14,3,2
2,3,2,12,2,3,2
2,3,2,11,2,3,2
2,3,16,12,15,3,2
2,3,18,12,17,3,2
2,3,19,12,19,3,2
2,3,19,12,19,3,2
2,3,21,12,20,3,2
2,3,23,12,22,3,2
2,3,2,11,2,3,2
2,3,12,12,12,3,2
2,3,12,12,12,3,2
2,3,12,12,12,3,2
2,3,12,12,12,3,2
2,3,2,11,2,3,2
2,3,12,12,12,3,2
2,3,24,12,24,3,2
2,3,12,12,12,3,2
2,3,12,25,12,3,2
2,3,2,2,2,3,2
2,2,3,3,3,2,2
1,2,2,2,2,2,1
1,2,2,2,2,2,1
1,2,2,2,2,2,1
1,1,2,2,2,1,1
1,1,1,2,1,1,1
endlayer

layer
1,1,4,4,4,1,1
1,1,1,5,1,1,1
2,2,2,5,2,2,2
1,2,2,5,2,2,1
1,1,2,5,2,1,1
1,2,2,5,2,2,1
1,2,2,5,2,2,1
1,2,5,5,5,2,1
1,2,27,5,26,2,1
2,2,5,5,5,2,2
2,2,8,8,8,2,2
2,2,8,8,8,2,2
2,2,3,3,3,2,2
2,3,8,8,8,3,2
2,3,9,9,9,3,2
2,3,10,10,10,3,2
2,3,10,28,10,3,2
2,3,10,10,10,3,2
2,3,2,29,2,3,2
2,3,2,10,2,3,2
2,3,13,10,13,3,2
2,3,14,10,14,3,2
2,3,2,10,2,3,2
2,3,13,10,13,3,2
2,3,14,10,14,3,2
2,3,2,10,2,3,2
2,3,13,10,13,3,2
2,3,14,10,14,3,2
2,3,2,10,2,3,2
2,3,2,29,2,3,2
2,3,31,10,30,3,2
2,3,33,10,32,3,2
2,3,19,10,19,3,2
2,3,19,10,19,3,2
2,3,35,10,34,3,2
2,3,37,10,36,3,2
2,3,2,29,2,3,2
2,3,38,10,38,3,2
2,3,38,10,38,3,2
2,3,38,10,38,3,2
2,3,38,10,38,3,2
2,3,2,29,2,3,2
2,3,39,10,39,3,2
2,3,10,10,10,3,2
2,3,10,10,10,3,2
2,3,10,10,10,3,2
2,3,9,9,9,3,2
2,2,3,3,3,2,2
2,2,2,2,2,2,2
2,2,2,2,2,2,2
1,2,2,2,2,2,1
1,2,2,2,2,2,1
1,1,2,2,2,1,1
endlayer

layer
1,1,1,4,1,1,1
1,1,1,1,1,1,1
1,1,1,2,1,1,1
1,1,1,2,1,1,1
1,1,1,2,1,1,1
1,1,2,2,2,1,1
1,1,2,2,2,1,1
1,2,5,5,5,2,1
1,2,6,40,6,2,1
1,2,5,5,5,2,1
1,2,8,8,8,2,1
1,2,8,8,8,2,1
1,2,3,3,3,2,1
2,3,8,8,8,3,2
2,3,9,9,9,3,2
2,3,41,10,41,3,2
2,3,10,10,10,3,2
2,3,41,10,41,3,2
2,3,2,2,2,3,2
2,3,2,10,2,3,2
2,3,13,10,13,3,2
2,3,14,10,14,3,2
2,3,2,10,2,3,2
2,3,13,10,13,3,2
2,3,14,10,14,3,2
2,3,2,10,2,3,2
2,3,13,10,13,3,2
2,3,14,10,14,3,2
2,3,2,10,2,3,2
2,3,2,2,2,3,2
2,3,43,10,42,3,2
2,3,45,10,44,3,2
2,3,19,10,19,3,2
2,3,19,10,19,3,2
2,3,47,10,46,3,2
2,3,49,10,48,3,2
2,3,2,2,2,3,2
2,3,38,10,38,3,2
2,3,38,10,38,3,2
2,3,38,10,38,3,2
2,3,38,10,38,3,2
2,3,2,2,2,3,2
2,3,10,10,10,3,2
2,3,10,10,10,3,2
2,3,10,10,10,3,2
2,3,10,10,10,3,2
2,3,2,2,2,3,2
1,2,3,3,3,2,1
1,2,2,2,2,2,1
1,2,2,2,2,2,1
1,1,2,2,2,1,1
1,1,2,2,2,1,1
1,1,1,2,1,1,1
endlayer

layer
1,1,1,1,1,1,1
1,1,1,1,1,1,1
1,1,1,2,1,1,1
1,1,1,2,1,1,1
1,1,1,1,1,1,1
1,1,1,2,1,1,1
1,1,1,2,1,1,1
1,1,2,2,2,1,1
1,1,2,2,2,1,1
1,1,2,2,2,1,1
1,1,2,2,2,1,1
1,2,2,2,2,2,1
1,2,2,2,2,2,1
1,2,3,3,3,2,1
1,2,3,3,3,2,1
1,2,3,3,3,2,1
1,2,3,3,3,2,1
1,2,3,3,3,2,1
1,2,3,3,3,2,1
1,2,3,3,3,2,1
1,2,3,3,3,2,1
1,2,3,3,3,2,1
1,2,3,3,3,2,1
1,2,3,3,3,2,1
1,2,3,3,3,2,1
1,2,3,3,3,2,1
1,2,3,3,3,2,1
1,2,3,3,3,2,1
1,2,3,3,3,2,1
1,2,3,3,3,2,1
1,2,3,3,3,2,1
1,2,3,3,3,2,1
1,2,3,3,3,2,1
1,2,3,3,3,2,1
1,2,3,3,3,2,1
1,2,3,3,3,2,1
1,2,3,3,3,2,1
1,2,3,3,3,2,1
1,2,3,3,3,2,1
1,2,3,3,3,2,1
1,2,3,3,3,2,1
1,2,3,3,3,2,1
1,2,3,3,3,2,1
1,2,3,3,3,2,1
1,2,3,3,3,2,1
1,2,3,3,3,2,1
1,2,3,3,3,2,1
1,2,2,2,2,2,1
1,1,2,2,2,1,1
1,1,2,2,2,1,1
1,1,2,2,2,1,1
1,1,1,2,1,1,1
1,1,1,1,1,1,1
endlayer

layer
1,1,1,1,1,1,1
1,1,1,1,1,1,1
1,1,1,2,1,1,1
1,1,1,1,1,1,1
1,1,1,1,1,1,1
1,1,1,1,1,1,1
1,1,1,1,1,1,1
1,1,1,1,1,1,1
1,1,1,1,1,1,1
1,1,1,2,1,1,1
1,1,1,2,1,1,1
1,1,1,2,1,1,1
1,1,1,2,1,1,1
1,1,2,2,2,1,1
1,1,2,2,2,1,1
1,1,2,2,2,1,1
1,1,2,2,2,1,1
1,1,2,2,2,1,1
1,1,2,2,2,1,1
1,1,2,2,2,1,1
1,1,2,2,2,1,1
1,1,2,2,2,1,1
1,1,2,2,2,1,1
1,1,2,2,2,1,1
1,1,2,2,2,1,1
1,1,2,2,2,1,1
1,1,2,2,2,1,1
1,1,2,2,2,1,1
1,1,2,2,2,1,1
1,1,2,2,2,1,1
1,1,2,2,2,1,1
1,1,2,2,2,1,1
1,1,2,2,2,1,1
1,1,2,2,2,1,1
1,1,2,2,2,1,1
1,1,2,2,2,1,1
1,1,2,2,2,1,1
1,1,2,2,2,1,1
1,1,2,50,2,1,1
1,1,2,2,2,1,1
1,1,2,2,2,1,1
1,1,2,2,2,1,1
1,1,2,2,2,1,1
1,1,2,2,2,1,1
1,1,2,2,2,1,1
1,1,2,2,2,1,1
1,1,2,2,2,1,1
1,1,1,2,1,1,1
1,1,1,2,1,1,1
1,1,1,2,1,1,1
1,1,1,1,1,1,1
1,1,1,1,1,1,1
1,1,1,1,1,1,1
endlayer

layer
1,1,1,1,1,1,1
1,1,1,1,1,1,1
1,1,1,1,1,1,1
1,1,1,1,1,1,1
1,1,1,1,1,1,1
1,1,1,1,1,1,1
1,1,1,1,1,1,1
1,1,1,1,1,1,1
1,1,1,1,1,1,1
1,1,1,1,1,1,1
1,1,1,1,1,1,1
1,1,1,1,1,1,1
1,1,1,1,1,1,1
1,1,1,1,1,1,1
1,1,1,1,1,1,1
1,1,1,1,1,1,1
1,1,1,1,1,1,1
1,1,1,1,1,1,1
1,1,1,1,1,1,1
1,1,1,1,1,1,1
1,1,1,1,1,1,1
1,1,1,1,1,1,1
1,1,1,1,1,1,1
1,1,1,1,1,1,1
1,1,1,1,1,1,1
1,1,1,1,1,1,1
1,1,1,1,1,1,1
1,1,1,1,1,1,1
1,1,1,1,1,1,1
1,1,1,1,1,1,1
1,1,1,1,1,1,1
1,1,1,1,1,1,1
1,1,1,1,1,1,1
1,1,1,1,1,1,1
1,1,1,2,1,1,1
1,1,1,2,1,1,1
1,1,2,2,2,1,1
1,1,2,2,2,1,1
1,1,2,10,2,1,1
1,1,1,2,1,1,1
1,1,1,1,1,1,1
1,1,1,1,1,1,1
1,1,1,1,1,1,1
1,1,1,1,1,1,1
1,1,1,1,1,1,1
1,1,1,1,1,1,1
1,1,1,1,1,1,1
1,1,1,1,1,1,1
1,1,1,1,1,1,1
1,1,1,1,1,1,1
1,1,1,1,1,1,1
1,1,1,1,1,1,1
1,1,1,1,1,1,1
endlayer

layer
1,1,1,1,1,1,1
1,1,1,1,1,1,1
1,1,1,1,1,1,1
1,1,1,1,1,1,1
1,1,1,1,1,1,1
1,1,1,1,1,1,1
1,1,1,1,1,1,1
1,1,1,1,1,1,1
1,1,1,1,1,1,1
1,1,1,1,1,1,1
1,1,1,1,1,1,1
1,1,1,1,1,1,1
1,1,1,1,1,1,1
1,1,1,1,1,1,1
1,1,1,1,1,1,1
1,1,1,1,1,1,1
1,1,1,1,1,1,1
1,1,1,1,1,1,1
1,1,1,1,1,1,1
1,1,1,1,1,1,1
1,1,1,1,1,1,1
1,1,1,1,1,1,1
1,1,1,1,1,1,1
1,1,1,1,1,1,1
1,1,1,1,1,1,1
1,1,1,1,1,1,1
1,1,1,1,1,1,1
1,1,1,1,1,1,1
1,1,1,1,1,1,1
1,1,1,1,1,1,1
1,1,1,1,1,1,1
1,1,1,1,1,1,1
1,1,1,1,1,1,1
1,1,1,1,1,1,1
1,1,1,2,1,1,1
1,1,1,2,1,1,1
51,51,2,2,2,51,51
51,51,2,2,2,51,51
1,51,2,10,2,51,1
1,1,1,2,1,1,1
1,1,1,1,1,1,1
1,1,1,1,1,1,1
1,1,1,1,1,1,1
1,1,1,1,1,1,1
1,1,1,1,1,1,1
1,1,1,1,1,1,1
1,1,1,1,1,1,1
1,1,1,1,1,1,1
1,1,1,1,1,1,1
1,1,1,1,1,1,1
1,1,1,1,1,1,1
1,1,1,1,1,1,1
1,1,1,1,1,1,1
endlayer

layer
1,1,1,1,1,1,1
1,1,1,1,1,1,1
1,1,1,1,1,1,1
1,1,1,1,1,1,1
1,1,1,1,1,1,1
1,1,1,1,1,1,1
1,1,1,1,1,1,1
1,1,1,1,1,1,1
1,1,1,1,1,1,1
1,1,1,1,1,1,1
1,1,1,1,1,1,1
1,1,1,1,1,1,1
1,1,1,1,1,1,1
1,1,1,1,1,1,1
1,1,1,1,1,1,1
1,1,1,1,1,1,1
1,1,1,1,1,1,1
1,1,1,1,1,1,1
1,1,1,1,1,1,1
1,1,1,1,1,1,1
1,1,1,1,1,1,1
1,1,1,1,1,1,1
1,1,1,1,1,1,1
1,1,1,1,1,1,1
1,1,1,1,1,1,1
1,1,1,1,1,1,1
1,1,1,1,1,1,1
1,1,1,1,1,1,1
1,1,1,1,1,1,1
1,1,1,1,1,1,1
1,1,1,1,1,1,1
1,1,1,1,1,1,1
1,1,1,1,1,1,1
1,1,1,1,1,1,1
1,1,1,2,1,1,1
1,1,1,2,1,1,1
1,1,2,2,2,1,1
1,1,2,2,2,1,1
1,1,2,52,2,1,1
1,1,1,2,1,1,1
1,1,1,1,1,1,1
1,1,1,1,1,1,1
1,1,1,1,1,1,1
1,1,1,1,1,1,1
1,1,1,1,1,1,1
1,1,1,1,1,1,1
1,1,1,1,1,1,1
1,1,1,1,1,1,1
1,1,1,1,1,1,1
1,1,1,1,1,1,1
1,1,1,1,1,1,1
1,1,1,1,1,1,1
1,1,1,1,1,1,1
endlayer

