weight=1
dimensionsToSpawnIn=overworld
embed_into_distance=1
random_height_offset=0,0
unacceptable_target_blocks=flowing_water,water,flowing_lava,lava,ice,packed_ice,stained_hardened_clay-9,brick_block,double_stone_slab,stonebrick,red_sandstone,red_nether_brick,red_mushroom_block,brown_mushroom_block,planks,cobblestone,end_stone,obsidian,purpur_block,iron_bars,purpur_slab,purpur_pillar,netherrack,soul_sand,quartz_ore
dimensions=39,13,13
allowable_overhang=0
max_leveling=1
leveling_buffer=-1
preventRotation=0
preserve_water=0
preserve_lava=0
uniqueMinDistance=1000
spawnMinDistance=500
spawnMaxDistance=0

rule1=0,100,minecraft:preserveBlock
rule2=0,100,minecraft:double_stone_slab-0
rule3=0,100,minecraft:stone_slab-0
rule4=0,100,minecraft:vine-8
rule5=0,100,minecraft:stone_slab-15
rule6=0,100,quark:iron_plate-0
rule7=0,100,minecraft:vine-1
rule8=0,100,minecraft:vine-4
rule9=0,100,CommandBlock:RUINSTRIGGER /setblock ~ ~-2 ~ mob_spawner 0 replace {SpawnCount:10,MaxNearbyEntities:10,SpawnRange:10,Delay:20,MinSpawnDelay:60,MaxSpawnDelay:120,RequiredPlayerRange:6,SpawnData:{id:"minecraft:endermite",ActiveEffects:[{Id:1,Amplifier:0,Duration:2147483647},{Id:14,Amplifier:0,Duration:2147483647}]}}:@-2
rule10=0,100,minecraft:vine-2
rule11=0,100,minecraft:quartz_stairs-0
rule12=0,100,minecraft:stone_brick_stairs-0
rule13=0,100,minecraft:redstone_lamp-0
rule14=0,100,minecraft:stone_brick_stairs-2
rule15=0,100,minecraft:stone_brick_stairs-3
rule16=0,100,minecraft:quartz_stairs-2
rule17=0,100,minecraft:quartz_stairs-3
rule18=0,100,minecraft:stone_brick_stairs-1
rule19=0,100,minecraft:quartz_stairs-1
rule20=0,100,minecraft:daylight_detector-11
rule21=0,100,minecraft:stone_slab-7
rule22=0,100,minecraft:quartz_block-2
rule23=0,100,minecraft:double_stone_slab-7
rule24=0,100,minecraft:iron_bars-0
rule25=0,100,minecraft:stained_hardened_clay-9
rule26=0,100,minecraft:vine-6
rule27=0,100,minecraft:vine-3
rule28=0,100,minecraft:vine-9
rule29=0,100,minecraft:stone_brick_stairs-4
rule30=0,100,minecraft:stone_brick_stairs-6
rule31=0,100,minecraft:stone_brick_stairs-7
rule32=0,100,minecraft:stone_brick_stairs-5
rule33=0,100,minecraft:quartz_stairs-5
rule34=0,100,minecraft:quartz_stairs-7
rule35=0,100,minecraft:quartz_stairs-6
rule36=0,100,minecraft:cobblestone_wall-0
rule37=0,100,minecraft:quartz_stairs-4
rule38=0,100,minecraft:diamond_block-0

layer
1,1,1,1,1,1,1,1,1,1,1,1,1
1,1,1,1,2,2,2,2,2,1,1,1,1
1,1,1,2,2,2,2,2,2,2,1,1,1
1,1,2,2,2,2,2,2,2,2,2,1,1
1,2,2,2,2,2,2,2,2,2,2,2,1
1,2,2,2,2,2,2,2,2,2,2,2,1
1,2,2,2,2,2,2,2,2,2,2,2,1
1,2,2,2,2,2,2,2,2,2,2,2,1
1,2,2,2,2,2,2,2,2,2,2,2,1
1,1,2,2,2,2,2,2,2,2,2,1,1
1,1,1,2,2,2,2,2,2,2,1,1,1
1,1,1,1,2,2,2,2,2,1,1,1,1
1,1,1,1,1,1,1,1,1,1,1,1,1
endlayer

layer
1,1,1,1,1,1,1,1,1,1,1,1,1
1,1,1,1,3,3,3,3,3,1,1,1,1
1,1,1,3,2,2,2,2,2,3,1,1,1
1,1,3,2,0,0,0,0,0,2,3,1,1
1,3,2,0,0,0,0,0,0,0,2,3,1
1,2,2,0,0,0,0,0,0,0,2,3,1
1,2,2,0,0,0,0,0,0,0,2,3,1
1,2,2,0,0,0,0,0,0,0,2,3,1
1,3,2,0,0,0,0,0,0,0,2,3,1
1,1,3,2,0,0,0,0,0,2,3,1,1
1,1,1,2,2,2,2,2,2,3,1,1,1
1,1,1,1,3,3,3,3,3,1,1,1,1
1,1,1,1,1,1,1,1,1,1,1,1,1
endlayer

layer
1,1,1,1,1,1,1,1,1,1,1,1,1
1,1,1,1,0,4,0,4,0,1,1,1,1
1,1,1,4,5,6,5,6,5,4,1,1,1
1,1,8,6,0,0,0,0,0,6,7,1,1
1,0,5,0,0,0,0,0,0,0,5,0,1
1,8,6,0,0,0,0,0,0,0,6,7,1
1,0,5,0,0,0,9,0,0,0,5,0,1
1,8,6,0,0,0,0,0,0,0,6,7,1
1,0,5,0,0,0,0,0,0,0,5,0,1
1,1,8,6,0,0,0,0,0,6,7,1,1
1,1,1,10,5,6,5,6,5,10,1,1,1
1,1,1,1,0,10,0,10,0,1,1,1,1
1,1,1,1,1,1,1,1,1,1,1,1,1
endlayer

layer
1,1,1,1,0,0,0,0,0,1,1,1,1
1,1,1,0,0,4,0,4,0,0,1,1,1
1,1,0,4,5,6,5,6,5,4,0,1,1
1,0,8,6,0,0,0,0,0,6,7,0,1
0,0,5,0,0,0,0,0,0,0,5,0,0
0,8,6,0,0,0,0,0,0,0,6,7,0
0,0,5,0,0,0,0,0,0,0,5,0,0
0,8,6,0,0,0,0,0,0,0,6,7,0
0,0,5,0,0,0,0,0,0,0,5,0,0
1,0,8,6,0,0,0,0,0,6,7,0,1
1,1,0,10,5,6,5,6,5,10,0,1,1
1,1,1,0,0,10,0,10,0,0,1,1,1
1,1,1,1,0,0,0,0,0,1,1,1,1
endlayer

layer
1,1,1,0,0,0,0,0,0,0,1,1,1
1,1,0,0,0,4,0,4,0,0,0,1,1
1,0,0,4,5,6,5,6,5,4,0,0,1
0,0,8,6,0,0,0,0,0,6,7,0,0
0,0,5,0,0,0,0,0,0,0,5,0,0
0,8,6,0,0,0,0,0,0,0,6,7,0
0,0,5,0,0,0,0,0,0,0,5,0,0
0,8,6,0,0,0,0,0,0,0,6,7,0
0,0,5,0,0,0,0,0,0,0,5,0,0
0,0,8,6,0,0,0,0,0,6,7,0,0
1,0,0,10,5,6,5,6,5,10,0,0,1
1,1,0,0,0,10,0,10,0,0,0,1,1
1,1,1,0,0,0,0,0,0,0,1,1,1
endlayer

layer
1,1,0,0,0,0,0,0,0,0,0,1,1
1,0,0,0,0,0,0,0,0,0,0,0,1
0,0,0,0,3,3,11,3,3,0,0,0,0
0,0,0,3,12,6,13,6,12,3,0,0,0
0,0,3,15,5,5,5,5,5,14,3,0,0
0,0,3,6,5,5,5,5,5,6,3,0,0
0,0,17,13,5,5,5,5,5,13,16,0,0
0,0,3,6,5,5,5,5,5,6,3,0,0
0,0,3,15,5,5,5,5,5,14,3,0,0
0,0,0,3,18,6,13,6,18,3,0,0,0
0,0,0,0,3,3,19,3,3,0,0,0,0
1,0,0,0,0,0,0,0,0,0,0,0,1
1,1,0,0,0,0,0,0,0,0,0,1,1
endlayer

layer
0,0,0,0,0,0,0,0,0,0,0,0,0
0,0,0,0,0,0,0,0,0,0,0,0,0
0,0,0,0,0,0,0,0,0,0,0,0,0
0,0,0,0,0,0,0,0,0,0,0,0,0
0,0,0,0,0,20,21,20,0,0,0,0,0
0,0,0,0,20,21,22,21,20,0,0,0,0
0,0,0,0,21,22,23,22,21,0,0,0,0
0,0,0,0,20,21,22,21,20,0,0,0,0
0,0,0,0,0,20,21,20,0,0,0,0,0
0,0,0,0,0,0,0,0,0,0,0,0,0
0,0,0,0,0,0,0,0,0,0,0,0,0
0,0,0,0,0,0,0,0,0,0,0,0,0
0,0,0,0,0,0,0,0,0,0,0,0,0
endlayer

layer
0,0,0,0,0,0,0,0,0,0,0,0,0
0,0,0,0,0,0,0,0,0,0,0,0,0
0,0,0,0,0,0,0,0,0,0,0,0,0
0,0,0,0,0,0,0,0,0,0,0,0,0
0,0,0,0,0,0,0,0,0,0,0,0,0
0,0,0,0,0,0,24,0,0,0,0,0,0
0,0,0,0,8,24,25,24,0,0,0,0,0
0,0,0,0,0,0,24,0,0,0,0,0,0
0,0,0,0,0,0,0,0,0,0,0,0,0
0,0,0,0,0,0,0,0,0,0,0,0,0
0,0,0,0,0,0,0,0,0,0,0,0,0
0,0,0,0,0,0,0,0,0,0,0,0,0
0,0,0,0,0,0,0,0,0,0,0,0,0
endlayer

layer
0,0,0,0,0,0,0,0,0,0,0,0,0
0,0,0,0,0,0,0,0,0,0,0,0,0
0,0,0,0,0,0,0,0,0,0,0,0,0
0,0,0,0,0,0,0,0,0,0,0,0,0
0,0,0,0,0,0,0,0,0,0,0,0,0
0,0,0,0,0,0,24,0,0,0,0,0,0
0,0,0,0,8,24,25,24,7,0,0,0,0
0,0,0,0,0,0,24,0,0,0,0,0,0
0,0,0,0,0,0,0,0,0,0,0,0,0
0,0,0,0,0,0,0,0,0,0,0,0,0
0,0,0,0,0,0,0,0,0,0,0,0,0
0,0,0,0,0,0,0,0,0,0,0,0,0
0,0,0,0,0,0,0,0,0,0,0,0,0
endlayer

layer
0,0,0,0,0,0,0,0,0,0,0,0,0
0,0,0,0,0,0,0,0,0,0,0,0,0
0,0,0,0,0,0,0,0,0,0,0,0,0
0,0,0,0,0,0,0,0,0,0,0,0,0
0,0,0,0,0,0,0,0,0,0,0,0,0
0,0,0,0,0,0,24,0,0,0,0,0,0
0,0,0,0,8,24,25,24,7,0,0,0,0
0,0,0,0,0,0,24,0,0,0,0,0,0
0,0,0,0,0,0,10,0,0,0,0,0,0
0,0,0,0,0,0,0,0,0,0,0,0,0
0,0,0,0,0,0,0,0,0,0,0,0,0
0,0,0,0,0,0,0,0,0,0,0,0,0
0,0,0,0,0,0,0,0,0,0,0,0,0
endlayer

layer
0,0,0,0,0,0,0,0,0,0,0,0,0
0,0,0,0,0,0,0,0,0,0,0,0,0
0,0,0,0,0,0,0,0,0,0,0,0,0
0,0,0,0,0,0,0,0,0,0,0,0,0
0,0,0,0,0,0,0,0,0,0,0,0,0
0,0,0,0,0,0,24,0,0,0,0,0,0
0,0,0,0,8,24,25,24,7,0,0,0,0
0,0,0,0,0,10,24,0,0,0,0,0,0
0,0,0,0,0,0,10,0,0,0,0,0,0
0,0,0,0,0,0,0,0,0,0,0,0,0
0,0,0,0,0,0,0,0,0,0,0,0,0
0,0,0,0,0,0,0,0,0,0,0,0,0
0,0,0,0,0,0,0,0,0,0,0,0,0
endlayer

layer
0,0,0,0,0,0,0,0,0,0,0,0,0
0,0,0,0,0,0,0,0,0,0,0,0,0
0,0,0,0,0,0,0,0,0,0,0,0,0
0,0,0,0,0,0,0,0,0,0,0,0,0
0,0,0,0,0,0,0,0,0,0,0,0,0
0,0,0,0,0,0,24,0,0,0,0,0,0
0,0,0,0,8,24,25,24,7,0,0,0,0
0,0,0,0,0,26,24,0,0,0,0,0,0
0,0,0,0,0,0,10,0,0,0,0,0,0
0,0,0,0,0,0,0,0,0,0,0,0,0
0,0,0,0,0,0,0,0,0,0,0,0,0
0,0,0,0,0,0,0,0,0,0,0,0,0
0,0,0,0,0,0,0,0,0,0,0,0,0
endlayer

layer
0,0,0,0,0,0,0,0,0,0,0,0,0
0,0,0,0,0,0,0,0,0,0,0,0,0
0,0,0,0,0,0,0,0,0,0,0,0,0
0,0,0,0,0,0,0,0,0,0,0,0,0
0,0,0,0,0,0,0,0,0,0,0,0,0
0,0,0,0,0,4,24,4,0,0,0,0,0
0,0,0,0,8,24,25,24,7,0,0,0,0
0,0,0,0,0,26,24,27,0,0,0,0,0
0,0,0,0,0,0,10,0,0,0,0,0,0
0,0,0,0,0,0,0,0,0,0,0,0,0
0,0,0,0,0,0,0,0,0,0,0,0,0
0,0,0,0,0,0,0,0,0,0,0,0,0
0,0,0,0,0,0,0,0,0,0,0,0,0
endlayer

layer
0,0,0,0,0,4,0,0,0,0,0,0,0
0,0,0,0,0,0,0,0,0,0,0,0,0
0,0,0,0,0,0,0,0,0,0,0,0,0
0,0,0,0,0,0,0,0,0,0,0,0,0
0,0,0,0,0,0,4,0,0,0,0,0,0
0,0,0,0,0,4,24,28,0,0,0,0,0
0,0,0,0,8,24,25,24,7,0,0,0,0
0,0,0,0,0,26,24,27,0,0,0,0,0
0,0,0,0,0,0,10,0,0,0,0,0,0
0,0,0,0,0,0,0,0,0,0,0,0,0
0,0,0,0,0,0,0,0,0,0,0,0,0
0,0,0,0,0,0,0,0,0,0,0,0,0
0,0,0,0,0,0,0,0,0,0,0,0,0
endlayer

layer
0,0,0,0,0,4,0,0,0,0,0,0,0
0,0,0,0,0,0,0,0,0,0,0,0,0
0,0,0,0,0,0,0,0,0,0,0,0,0
0,0,0,0,0,0,0,0,0,0,0,0,0
0,0,0,0,0,0,4,0,0,0,0,0,0
8,0,0,0,0,4,24,28,0,0,0,0,0
0,0,0,0,8,24,25,24,7,0,0,0,0
0,0,0,0,0,26,24,27,0,0,0,0,0
0,0,0,0,0,0,10,0,0,0,0,0,0
0,0,0,0,0,0,0,0,0,0,0,0,0
0,0,0,0,0,0,0,0,0,0,0,0,0
0,0,0,0,0,0,0,0,0,0,0,0,0
0,0,0,0,0,0,0,0,0,0,0,0,0
endlayer

layer
0,0,0,0,0,4,0,0,0,0,0,0,0
0,0,0,0,0,0,0,0,0,0,0,0,0
0,0,0,0,0,0,0,0,0,0,0,0,0
0,0,0,0,0,0,0,0,0,0,0,0,0
0,0,0,0,0,0,4,0,0,0,0,0,0
8,0,0,0,0,4,24,28,0,0,0,0,0
0,0,0,0,8,24,25,24,7,0,0,0,0
0,0,0,0,0,26,24,27,0,0,0,0,0
0,0,0,0,0,0,10,0,0,0,0,0,0
0,0,0,0,0,0,0,0,0,0,0,0,0
0,0,0,0,0,0,0,0,0,0,0,0,0
0,0,0,0,0,0,0,0,0,0,0,0,0
0,0,0,0,0,10,0,0,0,0,0,0,0
endlayer

layer
0,0,0,0,0,4,0,0,0,0,0,0,0
0,0,0,0,0,0,0,0,0,0,0,0,0
0,0,0,0,0,0,0,0,0,0,0,0,0
0,0,0,0,0,0,0,0,0,0,0,0,0
0,0,0,0,0,0,4,0,0,0,0,0,0
8,0,0,0,0,4,24,28,0,0,0,0,0
0,0,0,0,8,24,25,24,7,0,0,0,7
0,0,0,0,0,26,24,27,0,0,0,0,0
0,0,0,0,0,0,10,0,0,0,0,0,0
0,0,0,0,0,0,0,0,0,0,0,0,0
0,0,0,0,0,0,0,0,0,0,0,0,0
0,0,0,0,0,0,0,0,0,0,0,0,0
0,0,0,0,0,10,0,0,0,0,0,0,0
endlayer

layer
0,0,0,0,0,4,0,4,0,0,0,0,0
0,0,0,0,0,0,0,0,0,0,0,0,0
0,0,0,0,0,0,0,0,0,0,0,0,0
0,0,0,0,8,0,0,0,0,0,0,0,0
0,0,0,0,0,0,4,0,0,0,0,0,0
8,0,0,0,0,4,29,28,0,0,0,0,0
0,0,0,0,8,31,6,30,7,0,0,0,7
0,0,0,0,0,26,32,27,0,0,0,0,7
0,0,0,0,0,0,10,0,0,10,0,0,0
0,0,0,0,8,0,0,0,0,0,0,0,0
0,0,0,0,0,0,0,0,0,0,0,0,0
0,0,0,0,0,0,0,0,0,0,0,0,0
0,0,0,0,0,10,0,0,0,0,0,0,0
endlayer

layer
0,0,0,0,0,4,0,4,0,0,0,0,0
0,0,0,0,0,0,0,0,0,0,0,0,0
0,0,0,0,0,0,0,0,0,0,0,0,0
0,0,0,0,8,0,0,0,0,0,0,0,0
0,0,0,4,0,0,4,0,0,4,0,0,0
8,0,0,0,0,4,6,28,0,0,0,0,0
8,0,0,0,8,6,6,6,7,0,0,0,7
0,0,0,0,0,26,6,27,0,0,0,0,7
0,0,0,0,0,0,10,0,0,10,0,0,0
0,0,0,0,8,0,0,0,0,0,0,0,0
0,0,0,0,0,0,0,0,0,0,0,0,0
0,0,0,0,0,0,0,0,0,0,0,0,0
0,0,0,0,0,10,0,0,0,0,0,0,0
endlayer

layer
0,0,0,0,0,4,0,4,0,0,0,0,0
0,0,0,0,0,0,0,0,0,0,0,0,0
0,0,0,0,0,0,0,0,0,0,0,0,0
0,0,0,0,8,0,0,0,0,0,0,0,0
0,0,0,4,0,0,4,0,0,4,0,0,0
8,0,0,0,0,4,6,28,0,0,0,0,0
8,0,0,0,8,6,6,6,7,0,0,0,7
0,0,0,0,0,26,6,27,0,0,0,0,7
0,0,0,10,0,0,10,0,0,10,0,0,0
0,0,0,0,8,0,0,0,0,0,0,0,0
0,0,0,0,0,0,0,0,0,0,0,0,0
0,0,0,0,0,0,0,0,0,0,0,0,0
0,0,0,0,0,10,0,0,0,0,0,0,0
endlayer

layer
0,0,0,0,0,4,0,4,0,0,0,0,0
0,0,0,0,0,0,0,0,0,0,0,0,0
0,0,0,0,0,0,0,0,0,0,0,0,0
0,0,0,0,8,0,0,0,7,0,0,0,0
0,0,0,4,0,0,4,0,0,4,0,0,0
8,0,0,0,0,4,6,28,0,0,0,0,0
8,0,0,0,8,6,6,6,7,0,0,0,7
0,0,0,0,0,26,6,10,0,0,0,0,7
0,0,0,10,0,0,0,0,0,10,0,0,0
0,0,0,0,8,0,0,0,0,0,0,0,0
0,0,0,0,0,0,0,0,0,0,0,0,0
0,0,0,0,0,0,0,0,0,0,0,0,0
0,0,0,0,0,10,10,10,0,0,0,0,0
endlayer

layer
0,0,0,0,0,4,0,4,0,0,0,0,0
0,0,0,0,0,0,0,0,0,0,0,0,0
0,0,0,0,0,0,0,0,0,0,0,0,0
0,0,0,0,8,0,0,0,7,0,0,0,0
0,0,0,4,0,0,4,0,0,4,0,0,0
8,0,0,0,0,4,6,7,0,0,0,0,7
8,0,0,0,8,6,6,6,7,0,0,0,7
8,0,0,0,0,26,6,10,0,0,0,0,7
0,0,0,10,0,0,0,0,0,10,0,0,0
0,0,0,0,8,0,0,0,7,0,0,0,0
0,0,0,0,0,0,0,0,0,0,0,0,0
0,0,0,0,0,0,0,0,0,0,0,0,0
0,0,0,0,0,10,10,10,0,0,0,0,0
endlayer

layer
0,0,0,0,0,4,0,4,0,0,0,0,0
0,0,0,0,0,0,0,0,0,0,0,0,0
0,0,0,0,0,0,0,0,0,0,0,0,0
0,0,0,0,8,0,0,0,7,0,0,0,0
0,0,0,4,0,0,0,0,0,4,0,0,0
8,0,0,0,0,0,12,0,0,0,0,0,7
8,0,0,0,0,15,25,14,0,0,0,0,7
8,0,0,0,0,0,18,0,0,0,0,0,7
0,0,0,10,0,0,0,0,0,10,0,0,0
0,0,0,0,8,0,0,0,7,0,0,0,0
0,0,0,0,0,0,0,0,0,0,0,0,0
0,0,0,0,0,0,0,0,0,0,0,0,0
0,0,0,0,0,10,10,10,0,0,0,0,0
endlayer

layer
0,0,0,0,0,4,0,4,0,0,0,0,0
0,0,0,0,0,33,33,33,0,0,0,0,0
0,0,0,0,0,0,0,0,0,0,0,0,0
0,0,0,0,8,0,0,0,7,0,0,0,0
0,0,0,4,0,0,0,0,0,4,0,0,0
8,35,0,0,0,0,24,0,0,0,0,34,7
8,35,0,0,0,24,36,24,0,0,0,34,7
8,35,0,0,7,0,24,0,0,0,0,34,7
0,0,0,10,0,0,0,0,0,10,0,0,0
0,0,0,0,8,0,0,0,7,0,0,0,0
0,0,0,0,0,0,0,0,0,0,0,0,0
0,0,0,0,0,37,37,37,0,0,0,0,0
0,0,0,0,0,10,10,10,0,0,0,0,0
endlayer

layer
0,0,0,0,0,0,0,0,0,0,0,0,0
0,0,0,0,0,12,11,12,0,0,0,0,0
0,0,0,0,0,32,33,32,0,0,0,0,0
0,0,0,0,8,0,0,0,7,0,0,0,0
0,0,0,4,0,0,0,0,0,4,0,0,0
0,15,30,0,0,0,24,0,0,0,31,14,0
0,17,35,0,0,24,36,24,0,0,34,16,0
0,15,30,0,7,0,24,0,0,0,31,14,0
0,0,0,10,0,0,0,0,0,10,0,0,0
0,0,0,0,8,0,0,0,7,0,0,0,0
0,0,0,0,0,29,37,29,0,0,0,0,0
0,0,0,0,0,18,19,18,0,0,0,0,0
0,0,0,0,0,0,0,0,0,0,0,0,0
endlayer

layer
0,0,0,0,0,0,0,4,0,0,0,0,0
0,0,0,0,0,0,0,0,0,0,0,0,0
0,0,0,0,0,12,11,12,0,0,0,0,0
0,0,0,0,8,32,33,32,7,0,0,0,0
0,0,0,4,0,0,0,0,0,4,0,0,0
0,0,15,30,0,0,24,0,0,31,14,0,0
0,0,17,35,0,24,36,24,0,34,16,0,0
0,0,15,30,7,0,24,0,0,31,14,0,0
0,0,0,10,0,0,0,0,0,10,0,0,0
0,0,0,0,8,29,37,29,7,0,0,0,0
0,0,0,0,0,18,19,18,0,0,0,0,0
0,0,0,0,0,0,0,0,0,0,0,0,0
0,0,0,0,0,0,0,10,0,0,0,0,0
endlayer

layer
0,0,0,0,0,0,0,4,0,0,0,0,0
0,0,0,0,0,0,0,0,0,0,0,0,0
0,0,0,0,0,0,0,0,0,0,0,0,0
0,0,0,0,8,25,11,25,7,0,0,0,0
0,0,0,4,0,0,0,0,0,4,0,0,0
0,0,0,25,0,0,24,0,0,25,7,0,0
0,0,0,17,0,24,36,24,0,16,0,0,0
0,0,8,25,7,0,24,0,0,25,0,0,0
0,0,0,10,0,0,0,0,0,10,0,0,0
0,0,0,0,8,25,19,25,7,0,0,0,0
0,0,0,0,0,0,0,0,0,0,0,0,0
0,0,0,0,0,0,0,0,0,0,0,0,0
0,0,0,0,0,0,0,10,0,0,0,0,0
endlayer

layer
0,0,0,0,0,0,0,4,0,0,0,0,0
0,0,0,0,0,0,0,0,0,0,0,0,0
0,0,0,0,0,0,0,0,0,0,0,0,0
0,0,0,0,8,25,37,25,7,0,0,0,0
0,0,0,4,0,0,33,0,0,4,0,0,0
0,0,0,25,0,34,29,37,0,25,7,0,0
0,0,0,34,35,31,25,30,34,35,0,0,0
0,0,8,25,7,34,32,35,0,25,0,0,0
0,0,0,10,0,0,37,0,0,10,0,0,0
0,0,0,0,8,25,33,25,7,0,0,0,0
0,0,0,0,0,0,0,0,0,0,0,0,0
0,0,0,0,0,0,0,0,0,0,0,0,0
0,0,0,0,0,0,0,10,0,0,0,0,0
endlayer

layer
0,0,0,0,0,4,0,4,0,0,0,0,0
0,0,0,0,0,0,0,0,0,0,0,0,0
0,0,0,0,0,0,0,0,0,0,0,0,0
0,0,0,0,8,25,11,25,7,0,0,0,0
0,0,0,4,0,0,0,0,0,4,0,0,0
0,0,0,25,0,24,24,24,0,25,0,0,0
0,0,0,17,0,24,38,24,0,16,0,0,7
0,0,8,25,7,24,24,24,0,25,0,0,7
0,0,0,10,0,0,0,0,0,10,0,0,0
0,0,0,0,8,25,19,25,7,0,0,0,0
0,0,0,0,0,0,0,0,0,0,0,0,0
0,0,0,0,0,0,0,0,0,0,0,0,0
0,0,0,0,0,0,0,10,0,0,0,0,0
endlayer

layer
0,0,0,0,0,4,4,4,0,0,0,0,0
0,0,0,0,0,0,0,0,0,0,0,0,0
0,0,0,0,0,0,0,0,0,0,0,0,0
0,0,0,0,8,25,37,25,7,0,0,0,0
0,0,0,4,0,0,0,0,0,4,0,0,0
0,0,0,25,0,24,24,24,0,25,0,0,0
8,0,0,34,0,24,38,24,0,35,0,0,7
8,0,8,25,7,24,24,24,0,25,0,0,7
0,0,0,10,0,0,0,0,0,10,0,0,0
0,0,0,0,8,25,33,25,7,0,0,0,0
0,0,0,0,0,0,0,0,0,0,0,0,0
0,0,0,0,0,0,0,0,0,0,0,0,0
0,0,0,0,0,0,10,10,0,0,0,0,0
endlayer

layer
0,0,0,0,0,4,4,4,0,0,0,0,0
0,0,0,0,0,0,0,0,0,0,0,0,0
0,0,0,0,0,0,0,0,0,0,0,0,0
0,0,0,0,8,25,11,25,7,0,0,0,0
0,0,0,4,0,0,19,0,0,4,0,0,0
0,0,0,25,0,11,12,16,0,25,0,0,0
8,0,0,17,16,15,25,14,17,16,0,0,7
8,0,8,25,7,17,18,19,0,25,0,0,7
0,0,0,10,0,0,11,0,0,10,0,0,0
0,0,0,0,8,25,19,25,7,0,0,0,0
0,0,0,0,0,0,0,0,0,0,0,0,0
0,0,0,0,0,0,0,0,0,0,0,0,0
0,0,0,0,0,0,10,10,0,0,0,0,0
endlayer

layer
0,0,0,0,0,4,4,4,0,0,0,0,0
0,0,0,0,0,0,0,0,0,0,0,0,0
0,0,0,0,0,0,0,0,0,0,0,0,0
0,0,0,0,8,25,37,25,7,0,0,0,0
0,0,0,4,0,0,0,0,0,4,0,0,0
8,0,0,25,0,0,0,0,0,25,0,0,7
8,0,0,34,0,0,36,0,0,35,0,0,7
8,0,8,25,7,0,0,0,0,25,0,0,7
0,0,0,10,0,0,0,0,0,10,0,0,0
0,0,0,0,8,25,33,25,0,0,0,0,0
0,0,0,0,0,0,0,0,0,0,0,0,0
0,0,0,0,0,0,0,0,0,0,0,0,0
0,0,0,0,0,0,10,10,0,0,0,0,0
endlayer

layer
0,0,0,0,0,4,4,4,0,0,0,0,0
0,0,0,0,0,0,0,0,0,0,0,0,0
0,0,0,0,0,29,37,29,0,0,0,0,0
0,0,0,0,0,18,19,18,0,0,0,0,0
0,0,0,0,0,0,0,0,0,0,0,0,0
8,0,31,14,0,0,0,0,0,15,30,0,7
8,0,34,16,0,0,36,0,0,17,35,0,7
8,0,31,14,0,0,0,0,0,15,30,0,7
0,0,0,0,0,0,0,0,0,0,0,0,0
0,0,0,0,0,12,11,12,0,0,0,0,0
0,0,0,0,0,32,33,32,0,0,0,0,0
0,0,0,0,0,0,0,0,0,0,0,0,0
0,0,0,0,0,0,10,10,0,0,0,0,0
endlayer

layer
0,0,0,0,0,4,4,4,0,0,0,0,0
0,0,0,0,0,29,37,29,0,0,0,0,0
0,0,0,0,0,18,19,18,0,0,0,0,0
0,0,0,0,0,0,0,0,0,0,0,0,0
0,0,0,0,0,0,0,0,0,0,0,0,0
8,31,14,0,0,0,0,0,0,0,15,30,7
8,34,16,0,0,0,36,0,0,0,17,35,7
8,31,14,0,0,0,0,0,0,0,15,30,7
0,0,0,0,0,0,0,0,0,0,0,0,0
0,0,0,0,0,0,0,0,0,0,0,0,0
0,0,0,0,0,12,11,12,0,0,0,0,0
0,0,0,0,0,32,33,32,0,0,0,0,0
0,0,0,0,0,0,10,10,0,0,0,0,0
endlayer

layer
0,0,0,0,0,4,4,4,0,0,0,0,0
0,0,0,0,0,19,19,19,0,0,0,0,0
0,0,0,0,0,0,0,0,0,0,0,0,0
0,0,0,0,0,0,0,0,0,0,0,0,0
0,0,0,0,0,0,0,0,0,0,0,0,0
8,16,0,0,0,0,0,0,0,0,0,17,7
8,16,0,0,0,0,36,0,0,0,0,17,7
8,16,0,0,0,0,0,0,0,0,0,17,7
0,0,0,0,0,0,0,0,0,0,0,0,0
0,0,0,0,0,0,0,0,0,0,0,0,0
0,0,0,0,0,0,0,0,0,0,0,0,0
0,0,0,0,0,11,11,11,0,0,0,0,0
0,0,0,0,0,0,10,10,0,0,0,0,0
endlayer

layer
0,0,0,0,0,0,0,0,0,0,0,0,0
0,0,0,0,0,0,0,0,0,0,0,0,0
0,0,0,0,0,0,0,0,0,0,0,0,0
0,0,0,0,0,0,0,0,0,0,0,0,0
0,0,0,0,0,0,0,0,0,0,0,0,0
0,0,0,0,0,0,0,0,0,0,0,0,0
0,0,0,0,0,0,36,0,0,0,0,0,0
0,0,0,0,0,0,0,0,0,0,0,0,0
0,0,0,0,0,0,0,0,0,0,0,0,0
0,0,0,0,0,0,0,0,0,0,0,0,0
0,0,0,0,0,0,0,0,0,0,0,0,0
0,0,0,0,0,0,0,0,0,0,0,0,0
0,0,0,0,0,0,0,0,0,0,0,0,0
endlayer

layer
0,0,0,0,0,0,0,0,0,0,0,0,0
0,0,0,0,0,0,0,0,0,0,0,0,0
0,0,0,0,0,0,0,0,0,0,0,0,0
0,0,0,0,0,0,0,0,0,0,0,0,0
0,0,0,0,0,0,0,0,0,0,0,0,0
0,0,0,0,0,0,0,0,0,0,0,0,0
0,0,0,0,0,0,36,0,0,0,0,0,0
0,0,0,0,0,0,0,0,0,0,0,0,0
0,0,0,0,0,0,0,0,0,0,0,0,0
0,0,0,0,0,0,0,0,0,0,0,0,0
0,0,0,0,0,0,0,0,0,0,0,0,0
0,0,0,0,0,0,0,0,0,0,0,0,0
0,0,0,0,0,0,0,0,0,0,0,0,0
endlayer

layer
0,0,0,0,0,0,0,0,0,0,0,0,0
0,0,0,0,0,0,0,0,0,0,0,0,0
0,0,0,0,0,0,0,0,0,0,0,0,0
0,0,0,0,0,0,0,0,0,0,0,0,0
0,0,0,0,0,0,0,0,0,0,0,0,0
0,0,0,0,0,0,0,0,0,0,0,0,0
0,0,0,0,0,0,36,0,0,0,0,0,0
0,0,0,0,0,0,0,0,0,0,0,0,0
0,0,0,0,0,0,0,0,0,0,0,0,0
0,0,0,0,0,0,0,0,0,0,0,0,0
0,0,0,0,0,0,0,0,0,0,0,0,0
0,0,0,0,0,0,0,0,0,0,0,0,0
0,0,0,0,0,0,0,0,0,0,0,0,0
endlayer

layer
0,0,0,0,0,0,0,0,0,0,0,0,0
0,0,0,0,0,0,0,0,0,0,0,0,0
0,0,0,0,0,0,0,0,0,0,0,0,0
0,0,0,0,0,0,0,0,0,0,0,0,0
0,0,0,0,0,0,0,0,0,0,0,0,0
0,0,0,0,0,0,0,0,0,0,0,0,0
0,0,0,0,0,0,3,0,0,0,0,0,0
0,0,0,0,0,0,0,0,0,0,0,0,0
0,0,0,0,0,0,0,0,0,0,0,0,0
0,0,0,0,0,0,0,0,0,0,0,0,0
0,0,0,0,0,0,0,0,0,0,0,0,0
0,0,0,0,0,0,0,0,0,0,0,0,0
0,0,0,0,0,0,0,0,0,0,0,0,0
endlayer

