weight=3
dimensionsToSpawnIn=overworld
embed_into_distance=17
random_height_offset=0,0
unacceptable_target_blocks=flowing_water,water,flowing_lava,lava,ice,packed_ice,stained_hardened_clay-9,brick_block,double_stone_slab,stonebrick,red_sandstone,red_nether_brick,red_mushroom_block,brown_mushroom_block,planks,cobblestone,end_stone,obsidian,purpur_block,iron_bars,purpur_slab,purpur_pillar,netherrack,soul_sand,quartz_ore
dimensions=20,7,11
allowable_overhang=0
max_leveling=1
leveling_buffer=-1
preventRotation=0
preserve_water=0
preserve_lava=0
uniqueMinDistance=300
spawnMinDistance=0
spawnMaxDistance=0

rule1=0,100,minecraft:monster_egg-4,monster_egg-2,monster_egg-2,monster_egg-2,monster_egg-3,stonebrick-2,stonebrick-1,stonebrick-0,stonebrick-0,stonebrick-0
rule2=0,100,minecraft:cobblestone-0,mossy_cobblestone-0
rule3=0,100,minecraft:grass-0
rule4=0,100,minecraft:furnace-3
rule5=0,100,minecraft:stone_brick_stairs-2
rule6=0,100,minecraft:stone_brick_stairs-7
rule7=0,100,ChestGenHook:chests/village_blacksmith:5-5,ChestGenHook:chests/spawn_bonus_chest:9-5,ChestGenHook:chests/desert_pyramid:9-5
rule8=0,100,minecraft:stained_glass-7
rule9=0,100,minecraft:stone_slab-0
rule10=0,100,minecraft:water-0
rule11=0,100,minecraft:bed-3
rule12=0,100,minecraft:tallgrass-1
rule13=0,100,minecraft:bed-11
rule14=0,100,minecraft:stone_slab-3
rule15=0,100,minecraft:double_stone_slab-3
rule16=0,100,minecraft:cobblestone_wall-0
rule17=0,100,minecraft:stone_slab-8
rule18=0,100,minecraft:lever-2
rule19=0,100,minecraft:redstone_lamp-0
rule20=0,100,minecraft:anvil-0
rule21=0,100,minecraft:chest-4
rule22=0,100,minecraft:cauldron-0
rule23=0,100,minecraft:crafting_table-0
rule24=0,100,minecraft:hopper-4
rule25=0,100,ChestGenHook:chests/simple_dungeon:5-2,ChestGenHook:chests/jungle_temple_dispenser:9-2,ChestGenHook:chests/igloo_chest:7-2
rule26=0,100,minecraft:brewing_stand-0
rule27=0,100,minecraft:hopper-3
rule28=0,100,minecraft:furnace-4
rule29=0,100,minecraft:hopper-2
rule30=0,100,minecraft:hopper-0
rule31=0,100,minecraft:coal_block-0
rule32=0,100,minecraft:stone_brick_stairs-6
rule33=0,100,minecraft:stone_brick_stairs-3
rule34=0,100,minecraft:iron_bars-0
rule35=2,100,minecraft:stone_button-2
rule36=0,100,minecraft:stone_stairs-0
rule37=0,100,minecraft:piston-1
rule38=0,100,minecraft:stone_stairs-4
rule39=0,100,minecraft:dispenser-1
rule40=0,100,minecraft:stone_stairs-1
rule41=0,100,minecraft:stone_stairs-5
rule42=1,100,minecraft:stone_button-5
rule43=0,100,CommandBlock:RUINSTRIGGER /setblock ~ ~-2 ~ mob_spawner 0 replace {SpawnCount:3,MaxNearbyEntities:6,SpawnRange:12,Delay:20,MinSpawnDelay:60,MaxSpawnDelay:120,RequiredPlayerRange:32,SpawnData:{id:"minecraft:zombie",Health:30,Attributes:[{Name:"generic.maxHealth",Base:30}],HandItems:[{id:"minecraft:iron_sword",tag:{display:{Name:Nightstick}},Count:1},{}],HandDropChances:[0.05F,0F],ArmorItems:[{tag:{display:{Name:"Guard Boots"}},Count:1,id:"minecraft:iron_boots"},{tag:{display:{Name:"Guard Leggings"}},Count:1,id:"minecraft:iron_leggings"},{tag:{display:{Name:"Guard Chestplate"}},Count:1,id:"minecraft:iron_chestplate"},{id:"minecraft:iron_helmet",Count:1,tag:{display:{Name:"Guard Helmet"}}}],ArmorDropChances:[0.05F,0.05F,0.05F,0.05F]}}:@-4
rule44=0,100,preserveBlock
rule45=0,100,minecraft:iron_door-0
rule46=0,100,minecraft:stone_brick_stairs-1
rule47=0,100,minecraft:stone_brick_stairs-0
rule48=0,100,minecraft:stone_brick_stairs-4
rule49=0,100,minecraft:stone_brick_stairs-5
rule50=0,100,minecraft:iron_door-9
rule51=0,100,minecraft:stone_slab-5

layer
1,1,1,1,1,1,1,1,1,1,1
1,1,1,1,1,1,1,1,1,1,1
1,1,1,2,2,2,2,2,1,1,1
1,1,1,2,3,3,3,2,1,1,1
1,1,1,2,3,3,3,2,1,1,1
1,1,1,2,2,2,2,2,1,1,1
1,1,1,1,1,1,1,1,1,1,1
endlayer

layer
1,1,1,1,1,1,1,1,1,1,1
1,8,0,0,7,6,5,0,0,4,1
1,10,8,0,0,0,0,0,0,9,1
1,8,0,0,12,12,12,0,0,11,1
1,10,8,0,12,12,12,0,0,13,1
1,8,0,0,14,15,14,0,0,9,1
1,1,1,1,1,1,1,1,1,1,1
endlayer

layer
1,1,1,1,1,1,1,1,1,1,1
1,8,0,0,6,5,0,0,0,16,1
1,10,8,0,0,0,0,0,0,9,1
1,8,0,0,0,0,0,0,0,11,1
1,0,8,0,0,0,0,0,0,13,1
1,8,0,0,0,16,0,0,0,9,1
1,1,1,1,1,1,1,1,1,1,1
endlayer

layer
1,1,1,1,1,1,1,1,1,1,1
1,8,0,6,5,0,0,0,0,16,1
1,17,8,0,0,0,0,0,0,0,1
1,8,0,0,0,0,0,0,0,0,1
1,17,8,0,0,0,0,0,0,0,1
1,8,0,0,0,16,0,0,0,0,1
1,1,1,1,1,1,1,1,1,1,1
endlayer

layer
1,1,1,1,1,1,1,1,1,1,1
1,0,6,5,0,0,0,0,0,16,1
1,16,0,0,0,18,0,0,0,0,1
1,0,0,0,0,19,0,0,0,0,1
1,16,0,0,0,19,0,0,0,0,1
1,0,0,0,0,16,0,0,0,0,1
1,1,1,1,1,1,1,1,1,1,1
endlayer

layer
1,1,1,1,1,1,1,1,1,1,1
1,1,5,0,0,0,1,1,1,1,1
1,1,1,1,1,1,1,1,1,1,1
1,1,1,1,1,1,1,1,1,1,1
1,1,1,1,1,1,1,1,1,1,1
1,1,1,1,1,1,1,1,1,1,1
1,1,1,1,1,1,1,1,1,1,1
endlayer

layer
1,1,1,1,1,1,1,1,1,1,1
1,0,0,0,0,6,5,0,0,17,1
1,0,0,0,0,0,0,0,0,17,1
1,17,0,0,0,0,0,0,0,0,1
1,22,0,16,21,21,16,0,0,20,1
1,25,0,16,24,24,16,0,23,23,1
1,1,1,1,1,1,1,1,1,1,1
endlayer

layer
1,1,1,1,1,1,1,1,1,1,1
1,0,0,0,6,5,0,0,0,0,1
1,0,0,0,0,0,0,0,0,0,1
1,26,0,0,0,0,0,0,0,0,1
1,0,0,0,0,0,0,0,0,0,1
1,25,0,29,28,28,27,0,0,23,1
1,1,1,1,1,1,1,1,1,1,1
endlayer

layer
1,1,1,1,1,1,1,1,1,1,1
1,0,0,6,5,0,0,0,0,0,1
1,0,0,0,0,0,0,0,0,0,1
1,0,0,0,0,0,0,0,0,0,1
1,0,0,0,0,0,0,0,0,0,1
1,25,0,21,30,30,21,0,0,0,1
1,1,1,1,1,1,1,1,1,1,1
endlayer

layer
1,1,1,1,1,1,1,1,1,1,1
1,0,6,5,0,0,0,0,0,0,1
1,0,0,0,0,0,0,0,0,0,1
1,0,0,0,0,0,0,0,0,0,1
1,0,0,0,0,0,0,0,0,0,1
1,0,0,0,21,21,0,0,0,0,1
1,1,1,1,1,1,1,1,1,1,1
endlayer

layer
1,1,1,1,1,1,1,1,1,1,1
1,1,5,0,0,0,6,1,1,1,1
1,1,1,1,1,1,1,1,1,1,1
1,1,1,1,1,1,1,1,1,1,1
1,1,1,1,1,1,1,1,1,1,1
1,1,1,1,1,1,1,1,1,1,1
1,1,1,1,1,1,1,1,1,1,1
endlayer

layer
1,1,1,1,1,1,1,1,1,1,1
1,0,0,0,0,0,0,0,31,31,1
1,0,33,32,0,0,0,0,0,4,1
1,0,0,35,0,0,34,34,34,34,1
1,0,16,39,38,9,38,37,37,36,1
1,0,16,39,41,17,41,37,37,40,1
1,1,1,1,1,1,1,1,1,1,1
endlayer

layer
1,1,1,1,1,1,1,1,1,1,1
1,0,0,0,0,0,0,0,0,31,1
1,0,0,33,32,0,0,0,0,16,1
1,0,0,35,0,0,34,34,34,34,1
1,0,33,39,36,9,36,20,20,38,1
1,0,33,39,40,17,40,20,20,41,1
1,1,1,1,1,1,1,1,1,1,1
endlayer

layer
1,1,1,1,1,1,1,1,1,1,1
1,0,0,0,0,0,0,0,0,0,1
1,0,0,0,33,32,0,0,0,16,1
1,0,0,0,0,0,0,0,0,16,1
1,0,0,42,0,0,0,9,9,16,1
1,0,0,42,0,0,0,9,9,43,1
1,1,1,1,1,1,1,1,1,1,1
endlayer

layer
1,1,1,1,1,1,1,1,1,1,1
1,0,0,0,0,0,0,0,0,0,1
1,0,0,0,0,33,32,0,0,0,1
1,0,0,0,0,0,0,0,0,0,1
1,0,0,0,0,0,0,0,0,0,1
1,0,0,0,0,0,0,0,0,0,1
1,1,1,1,1,1,1,1,1,1,1
endlayer

layer
1,1,1,1,1,1,1,1,1,1,1
1,1,1,1,1,1,1,1,1,1,1
1,1,32,0,0,0,33,1,1,1,1
1,1,1,1,1,1,1,1,1,1,1
1,1,1,1,1,1,1,1,1,1,1
1,1,1,1,1,1,1,1,1,1,1
1,1,1,1,1,1,1,1,1,1,1
endlayer

layer
44,44,44,1,44,44,44,1,44,44,44
44,1,1,1,1,1,1,1,1,1,44
44,1,1,32,0,0,0,33,1,1,44
44,1,1,1,1,1,1,1,1,1,44
44,1,1,1,1,1,1,1,1,1,44
44,1,1,1,1,1,1,1,1,1,44
44,44,44,1,1,44,1,1,44,44,44
endlayer

layer
44,44,44,1,44,44,44,1,44,44,44
44,1,1,1,1,1,1,1,1,1,44
44,1,1,0,0,0,0,0,1,1,44
44,1,1,0,0,0,0,0,1,1,44
44,6,1,1,1,45,1,1,1,32,44
44,46,1,1,1,0,1,1,1,46,44
44,44,44,46,44,0,44,46,44,44,44
endlayer

layer
44,44,44,47,44,44,44,47,44,44,44
44,16,1,1,48,48,48,1,1,16,44
44,44,6,0,0,0,0,0,32,44,44
44,44,6,0,35,0,0,0,32,44,44
44,33,1,49,1,50,1,49,1,5,44
44,44,44,44,46,0,46,44,44,44,44
44,44,44,0,0,0,0,0,44,44,44
endlayer

layer
44,0,0,0,0,0,0,0,0,0,44
0,0,47,47,47,47,47,47,5,0,0
0,0,33,1,1,1,1,1,5,0,0
0,0,33,1,1,1,1,1,5,0,0
0,0,46,46,1,1,1,46,46,0,0
44,0,0,0,51,46,51,0,0,0,44
44,44,0,0,0,0,0,0,0,44,44
endlayer

