weight=8
dimensionsToSpawnIn=overworld
embed_into_distance=1
random_height_offset=0,0
unacceptable_target_blocks=flowing_water,water,flowing_lava,lava,ice,packed_ice,stained_hardened_clay-9,brick_block,double_stone_slab,stonebrick,red_sandstone,red_nether_brick,red_mushroom_block,brown_mushroom_block,planks,cobblestone,end_stone,obsidian,purpur_block,iron_bars,purpur_slab,purpur_pillar,netherrack,soul_sand,quartz_ore
dimensions=8,9,9
allowable_overhang=0
max_leveling=1
leveling_buffer=-1
preventRotation=0
preserve_water=0
preserve_lava=0
uniqueMinDistance=0
spawnMinDistance=0
spawnMaxDistance=0

rule1=0,100,preserveBlock
rule2=0,100,minecraft:gravel-0,gravel-0,preserveBlock
rule3=0,100,minecraft:gravel-0
rule4=0,100,MobSpawner:Silverfish,MobSpawner:Silverfish,MobSpawner:Silverfish,gravel-0

layer
1,1,1,2,2,2,1,1,1
1,1,2,3,4,3,2,1,1
1,2,3,3,3,3,3,2,1
2,3,3,4,4,3,4,4,2
2,3,3,3,3,3,4,3,2
2,3,3,3,3,3,3,3,2
1,2,4,3,3,3,4,2,1
1,1,2,4,3,3,2,1,1
1,1,1,2,2,2,1,1,1
endlayer

layer
1,1,0,0,0,0,0,1,1
1,0,0,2,3,2,0,0,1
0,0,3,3,3,3,2,0,0
0,2,4,3,3,4,3,2,0
0,2,3,3,3,3,3,2,0
0,3,3,4,3,3,3,3,0
0,0,3,3,3,3,2,0,0
1,0,0,3,2,3,0,0,1
1,1,0,0,0,0,0,1,1
endlayer

layer
1,0,0,0,0,0,0,0,1
0,0,0,2,2,2,0,0,0
0,0,3,2,3,2,2,0,0
0,2,2,2,2,2,3,2,0
0,2,2,3,2,2,2,2,0
0,3,2,2,2,3,2,3,0
0,0,2,3,2,2,0,0,0
0,0,0,2,2,3,0,0,0
1,0,0,0,0,0,0,0,1
endlayer

layer
0,0,0,0,0,0,0,0,0
0,0,0,0,0,0,0,0,0
0,0,3,0,3,0,0,0,0
0,0,0,0,2,2,3,0,0
0,0,0,3,2,0,0,0,0
0,3,0,2,2,3,0,3,0
0,0,0,3,0,0,0,0,0
0,0,0,0,0,3,0,0,0
0,0,0,0,0,0,0,0,0
endlayer

layer
0,0,0,0,0,0,0,0,0
0,0,0,0,0,0,0,0,0
0,0,2,0,3,0,0,0,0
0,0,0,0,0,0,2,0,0
0,0,0,3,0,0,0,0,0
0,3,0,0,0,3,0,2,0
0,0,0,2,0,0,0,0,0
0,0,0,0,0,2,0,0,0
0,0,0,0,0,0,0,0,0
endlayer

layer
0,0,0,0,0,0,0,0,0
0,0,0,0,0,0,0,0,0
0,0,2,0,2,0,0,0,0
0,0,0,0,0,0,2,0,0
0,0,0,2,0,0,0,0,0
0,2,0,0,0,2,0,2,0
0,0,0,2,0,0,0,0,0
0,0,0,0,0,2,0,0,0
0,0,0,0,0,0,0,0,0
endlayer

layer
0,0,0,0,0,0,0,0,0
0,0,0,0,0,0,0,0,0
0,0,2,0,2,0,0,0,0
0,0,0,0,0,0,2,0,0
0,0,0,2,0,0,0,0,0
0,2,0,0,0,2,0,2,0
0,0,0,2,0,0,0,0,0
0,0,0,0,0,2,0,0,0
0,0,0,0,0,0,0,0,0
endlayer

layer
0,0,0,0,0,0,0,0,0
0,0,0,0,0,0,0,0,0
0,0,0,0,2,0,0,0,0
0,0,0,0,0,0,0,0,0
0,0,0,2,0,0,0,0,0
0,0,0,0,0,2,0,0,0
0,0,0,0,0,0,0,0,0
0,0,0,0,0,0,0,0,0
0,0,0,0,0,0,0,0,0
endlayer

